<mujoco model="ARM">
    <compiler angle="radian" />
    <size njmax="500" nconmax="100" />
    <asset>
        <mesh name="base_link" file="base_link.STL" />
        <mesh name="Link1" file="Link1.STL" />
        <mesh name="Link2" file="Link2.STL" />
        <mesh name="Link3" file="Link3.STL" />
        <mesh name="Link4" file="Link4.STL" />
        <mesh name="Link5" file="Link5.STL" />
    </asset>
    <worldbody>
        <geom type="mesh" rgba="0.8902 0.8902 0.91373 1" mesh="base_link" />
        <body name="Link1" pos="0 0.081 0" quat="0.707105 -0.707108 0 0">
            <inertial pos="-0.00035044 -0.0006963 0.042913" quat="0.726584 0.036731 -0.0280933 0.68552" mass="0.81892" diaginertia="0.000774832 0.000704618 0.000586156" />
            <joint name="Joint1" pos="0 0 0" axis="0 0 1" limited="true" range="-5000 5000" />
            <geom type="mesh" rgba="0.8902 0.8902 0.91373 1" mesh="Link1" />
            <body name="Link2" pos="0 0.035 0.05" quat="0.707105 0.707108 0 0">
                <inertial pos="0.20462 1.2116e-05 0.034741" quat="0.499974 0.500034 0.500062 0.49993" mass="0.76516" diaginertia="0.0193544 0.0188793 0.000847747" />
                <joint name="Joint2" pos="0 0 0" axis="0 0 -1" limited="true" range="-5000 5000" />
                <geom type="mesh" rgba="0.79216 0.81961 0.93333 1" mesh="Link2" />
                <body name="Link3" pos="0.384 0 0.0115" quat="0.499998 0 0 0.866027">
                    <inertial pos="0.031638 0.002191 0.024569" quat="0.0755585 0.715142 -0.0121841 0.694776" mass="0.84476" diaginertia="0.00219327 0.00194685 0.000582734" />
                    <joint name="Joint3" pos="0 0 0" axis="0 0 -1" limited="true" range="-5000 5000" />
                    <geom type="mesh" rgba="0.8902 0.8902 0.91373 1" mesh="Link3" />
                    <body name="Link4" pos="0.10116 0.034303 0.0235" quat="0.683011 -0.683014 0.183013 -0.183013">
                        <inertial pos="0 0 0.15264" quat="1 0 0 -0.000313515" mass="0.18955" diaginertia="0.0021653 0.00215581 6e-05" />
                        <joint name="Joint4" pos="0 0 0" axis="0 0 1" limited="true" range="-5000 5000" />
                        <geom type="mesh" rgba="0.8902 0.8902 0.91373 1" mesh="Link4" />
                        <body name="Link5" pos="0 -0.0245 0.3172" quat="0.499998 0.5 -0.5 0.500002">
                            <inertial pos="0.021578 -6.0828e-11 -0.025035" quat="0.494567 0.505374 0.505374 0.494567" mass="0.18828" diaginertia="9.86327e-05 8.66423e-05 5.24962e-05" />
                            <joint name="Joint5" pos="0 0 0" axis="0 0 -1" limited="true" range="-5000 5000" />
                            <geom type="mesh" rgba="1 1 1 1" mesh="Link5" />
                        </body>
                    </body>
                </body>
            </body>
        </body>
    </worldbody>
</mujoco>
