<mujoco model="Xiaotian_Arm_v3">
 <compiler angle="radian" meshdir="arm_meshes_v3" balanceinertia="false" />
	<size njmax="500" nconmax="100" />
	<option gravity="0 0 -9.806" iterations="50" solver="Newton" timestep="0.002" />
	<default>
		<geom contype="1" conaffinity="1" friction="0.6 0.3 0.3" rgba="0.5 0.6 0.7 0.6" margin="0.001" group="0" />
		<default class="visual">
			<geom contype="0" conaffinity="0" group="1" type="mesh" rgba="0.9 0.9 0.9 1.0" />
		</default>
		<light castshadow="false" diffuse="1 1 1" />
		<motor ctrllimited="true" />
		<camera fovy="60" />
		<joint damping="0.01" armature="0.01" />
	</default>

    <asset>
        <mesh name="base_link" file="base_link.STL" />
        <mesh name="actuator1" file="actuator1.STL" />
        <mesh name="actuator2" file="actuator2.STL" />
        <mesh name="actuator3" file="actuator3.STL" />
        <mesh name="actuator4" file="actuator4.STL" />
        <mesh name="actuator5" file="actuator5.STL" />
        <mesh name="actuator6" file="actuator6.STL" />
        <mesh name="gripper" file="gripper.STL" />
    </asset>

    <asset>
		<texture type="skybox" builtin="gradient" rgb1="1.0 1.0 1.0" rgb2="1.0 1.0 1.0" width="512" height="512" />
		<texture name="plane" type="2d" builtin="flat" rgb1="1 1 1" rgb2="1 1 1" width="512" height="512" mark="cross" markrgb="0 0 0" />
		<material name="plane" reflectance="0.0" texture="plane" texrepeat="3 3" texuniform="true" />
	</asset>

    <visual>
		<rgba com="0.502 1.0 0 0.5" contactforce="0.2 0.98 0.2 0.8" contactpoint="1.0 1.0 0.6 0.4" />
		<scale com="0.2" forcewidth="0.05" contactwidth="0.10" contactheight="0.04" />
	</visual>

    <worldbody>
        <light directional="true" diffuse=".8 .8 .8" pos="0 0 10" dir="0 0 -10" />
		<camera name="track" mode="trackcom" pos="0 -1.3 1.6" xyaxes="1 0 0 0 0.707 0.707" />
		<geom name="floor" type="plane" conaffinity="1" condim="3" contype="1" rgba="1 1 1 1" material="plane" pos="0 0 0" size="0 0 1" />
		
        <!-- base -->
        <body name='base_Link' pos = '0 0 0' euler='0 0 0'>
            <geom type='mesh' mesh='base_link' class='visual' />
            <inertial pos='-0.00048925 0.040872 -1.6257E-08' mass='0.380' fullinertia='3.254146E-05 3.269992E-05 2.282150E-05 -6.730E-08 -1.9753E-07 -1.681E-08' />
            <site name='imu' pos='0 0 0' />

            <!-- link1 -->
            <body name="actuator1" pos="0 0 0.06789">
                <joint name="joint1" type="hinge" pos="0 0 0" axis="0 0 1" limited="true" range="-3.14 3.14" frictionloss="0.0" />
                <inertial pos="9.172e-06 -0.0038593 0.042337" quat="0.510363 0.859959 -0.000491191 0.000598962" mass="1.16414" diaginertia="0.000655353 0.00053265 0.000419688" />
                <geom type="mesh" rgba="0.89804 0.91765 0.92941 1" mesh="actuator1" />
                
                <!-- link 2-->
                <body name="actuator2" pos="-0.010103 -0.048969 0.054" quat="0.707105 -0.707108 0 0">
                    <joint name="joint2" type="hinge" pos="0 0 0" axis="-0.20207 0 -0.979371" limited="true" range="-3.14 3.14" frictionloss="0.0" />
                    <inertial pos="-0.15554 5.3314e-06 0.045289" quat="0.503186 0.496691 0.496679 0.5034" mass="0.7699" diaginertia="0.0141425 0.0138086 0.000572137" />
                    <geom type="mesh" rgba="0.89804 0.91765 0.92941 1" mesh="actuator2" />
                
                    <!-- link3 -->
                    <body name="actuator3" pos="-0.3239 0 0.012478">
                        <joint name="joint3" pos="0 0 0" axis="0 0 1" limited="true" range="-3.14 3.14" frictionloss="0.0" />
                        <inertial pos="0.096602 -0.058308 0.032914" quat="0.540418 0.364098 0.602167 0.461276" mass="0.72893" diaginertia="0.00535321 0.00530349 0.000472276" />
                        <geom type="mesh" rgba="0.89804 0.91765 0.92941 1" mesh="actuator3" />

                        <!-- link4 -->
                        <body name="actuator4" pos="0.20571 -0.072177 -0.00099033" quat="0.999437 0 0 -0.0335407">
                            <joint name="joint4" pos="0 0 0" axis="0 0 1" limited="true" range="-3.14 3.14" frictionloss="0.0" />
                            <inertial pos="0.042348 -0.00057806 0.032474" quat="0.422243 0.497559 0.650081 0.389283" mass="0.51931" diaginertia="0.000416076 0.000372556 0.000238225" />
                            <geom type="mesh" rgba="0.79216 0.81961 0.93333 1" mesh="actuator4" />

                            <!-- link5 -->
                            <body name="actuator5" pos="0.0665 -0.036429 0.0365" quat="0.707105 0.707108 0 0">
                                <joint name="joint5" pos="0 0 0" axis="-0.00388711 0 -0.999992" limited="true" range="-3.14 3.14" frictionloss="0.0" />
                                <inertial pos="0.052455 7.6209e-06 -0.03329" quat="0.568312 0.420666 0.420191 0.568772" mass="0.5168" diaginertia="0.000499915 0.000395659 0.000211719" />
                                <geom type="mesh" rgba="0.79216 0.81961 0.93333 1" mesh="actuator5" />

                                <!-- link6 -->
                                <body name="actuator6" pos="0.10299 0 -0.0375" quat="0.499998 0.5 0.500002 0.5">
                                    <joint name="joint6" pos="0 0 0" axis="0 0.00388711 -0.999992" limited="true" range="-3.14 3.14" frictionloss="0.0" />
                                    <inertial pos="0.0048827 -0.00030958 0.061809" quat="0.696778 -0.0372658 0.0361374 0.715406" mass="0.26669" diaginertia="0.000405458 0.000387234 8.89835e-05" />
                                    <geom type="mesh" rgba="0.53333 0.85098 0.82353 1" mesh="actuator6" />

                                    <!-- gripper -->
                                    <body name="gripper" pos="0 0.0235 0.061" quat="0.516489 -0.482949 -0.482947 -0.516491">
                                        <joint name="Gripper_link" pos="0 0 0" axis="0.067044 0 -0.99775" limited="true" range="-3.14 3.14" frictionloss="0.0" />
                                        <inertial pos="0.047354 -0.013359 -0.020482" quat="0.523188 0.489063 0.472344 0.513793" mass="0.062634" diaginertia="8.82937e-05 6.39098e-05 2.97084e-05" />
                                        <geom type="mesh" rgba="0.29804 0.29804 0.29804 1" mesh="gripper" />
                                    </body>
                                </body>
                            </body>
                        </body>
                    </body>
                </body>
            </body>
        </body>
    </worldbody>

     <actuator>
		<!-- position controller -->
        <position name="joint1_pos" joint="joint1" gear="1" kp="50" ctrllimited="true" ctrlrange="-6.28 6.28" />
        <position name="joint2_pos" joint="joint2" gear="1" kp="50" ctrllimited="true" ctrlrange="-6.28 6.28" />
        <position name="joint3_pos" joint="joint3" gear="1" kp="50" ctrllimited="true" ctrlrange="-6.28 6.28" />
        <position name="joint4_pos" joint="joint4" gear="1" kp="50" ctrllimited="true" ctrlrange="-6.28 6.28" />
        <position name="joint5_pos" joint="joint5" gear="1" kp="50" ctrllimited="true" ctrlrange="-6.28 6.28" />
        <position name="joint6_pos" joint="joint6" gear="1" kp="50" ctrllimited="true" ctrlrange="-6.28 6.28" />
        <position name="joint7_pos" joint="Gripper_link" gear="1" kp="10" ctrllimited="true" ctrlrange="-6.28 6.28" />
        <!-- velocity controller -->
		<velocity name="joint1_vel" joint="joint1" gear="1" kv="3" ctrllimited="false" />
		<velocity name="joint2_vel" joint="joint2" gear="1" kv="3" ctrllimited="false" />
		<velocity name="joint3_vel" joint="joint3" gear="1" kv="3" ctrllimited="false" />
		<velocity name="joint4_vel" joint="joint4" gear="1" kv="3" ctrllimited="false" />
		<velocity name="joint5_vel" joint="joint5" gear="1" kv="3" ctrllimited="false" />
        <velocity name="joint6_vel" joint="joint6" gear="1" kv="3" ctrllimited="false" />
        <velocity name="joint7_vel" joint="Gripper_link" gear="1" kv="3" ctrllimited="false" />
        <!-- torque controller -->
        <motor name="actuator1" joint="joint1" gear="1" ctrllimited="true" ctrlrange="-20 20" />
		<motor name="actuator2" joint="joint2" gear="1" ctrllimited="true" ctrlrange="-40 40" />
		<motor name="actuator3" joint="joint3" gear="1" ctrllimited="true" ctrlrange="-20 20" />
		<motor name="actuator4" joint="joint4" gear="1" ctrllimited="true" ctrlrange="-20 20" />
		<motor name="actuator5" joint="joint5" gear="1" ctrllimited="true" ctrlrange="-20 20" />
		<motor name="actuator6" joint="joint6" gear="1" ctrllimited="true" ctrlrange="-20 20" />
        <motor name="actuator7" joint="Gripper_link" gear="1" ctrllimited="true" ctrlrange="-20 20" />
	</actuator>
	<sensor>
		<!-- sensordata index from 0-6 -->
		<jointpos name="Link1" joint="joint1" />
		<jointpos name="Link2" joint="joint2" />
		<jointpos name="Link3" joint="joint3" />
		<jointpos name="Link4" joint="joint4" />
		<jointpos name="Link5" joint="joint5" />
        <jointpos name="Link6" joint="joint6" />
        <jointpos name="Link7" joint="Gripper_link" />
		<!-- sensordata index from 7-13 -->
		<jointvel name="Link1_vel" joint="joint1" />
		<jointvel name="Link2_vel" joint="joint2" />
		<jointvel name="Link3_vel" joint="joint3" />
		<jointvel name="Link4_vel" joint="joint4" />
		<jointvel name="Link5_vel" joint="joint5" />
        <jointvel name="Link6_vel" joint="joint6" />
        <jointvel name="Link7_vel" joint="Gripper_link" />
	</sensor>
    
</mujoco>
